Workbook

Sheet Leyenda
A1: RedVital — Tareas del Sprint 3
A2: Entrega | B2: Semana 10 — Review Sprint 3 y Planning Sprint 4 (alrededor del 13–14 de octubre de 2026)
A3: Fuente | B3: Backlog del Sprint 3 v1.2, con la historia de Identidad dividida en dos: HU-304 (inicio de sesión y claves públicas, 3 pts) y HU-330 (renovación, término, token de servicio y auditoría, 2 pts).
A5: Cómo usar
A6: Filtrar | B6: En la hoja Tareas, usa las flechas del encabezado: Responsable, Frente, Tipo, Entregable S10, Ruta crítica, Nivel o Estado.
A7: Celdas para editar | B7: Las de fondo amarillo claro: Estado (lista desplegable), Fecha inicio y Fecha fin en la hoja Tareas; y los dos supuestos en azul de la hoja Carga por persona.
A8: Formato de fecha | B8: dd/mm/aaaa, por ejemplo 05/10/2026. Si la fecha fin queda antes que la de inicio, se marca en rojo.
A9: Estados | B9: Pendiente · En curso (amarillo) · Bloqueada (rojo) · Hecha (verde). Las hojas Historias y Carga por persona recalculan el avance a partir del Estado.
A11: Columnas
A12: Depende de | B12: Tareas que deben estar terminadas para poder cerrar esta. Las tareas de pruebas se pueden empezar a escribir antes, contra el contrato publicado en T-301.5.
A13: Bloquea a | B13: Tareas que esperan a esta. Se generó a partir de «Depende de»; si cambias una dependencia, actualiza también esta columna.
A14: Nivel | B14: Longitud de la cadena de dependencias más larga que llega a la tarea. Nivel 0 = no depende de nada y puede empezar el primer día. Una tarea no puede empezar antes que todas sus dependencias, que siempre tienen un nivel menor. Sirve para ordenar al cuadrar fechas.
A15: Ruta crítica | B15: Sí cuando la historia está en una de las dos cadenas más largas: Contratos → Donación → Motor → Tamizaje → Inventario → QA → Informe → TD V1 → Presentación, y Contratos → Identidad → Gateway → QA.
A16: Tipo | B16: Código · Base de datos · Pruebas · Infraestructura · Diagrama · Documento · Gestión.
A17: Pts | B17: Los puntos viven en la hoja Historias; las tareas no se estiman.
A19: Tareas para agendar primero
A20: T-303.1 | B20: Llave de prueba: desbloquea a Damián y a Tomás sin esperar a Identidad.
A21: T-304.1, T-306.1, T-312.1 | B21: Esquemas de las tres bases: los necesita el generador de datos sintéticos (T-302.2).
A22: T-301.1 a T-301.5 | B22: Contratos: casi todo el código y las pruebas dependen de ellos.
A23: T-322.3 | B23: Resolver RDS-13 (ciclo de vencimiento): bloquea el proceso de vencimiento (T-311.1).
A24: T-314.1 | B24: Confirmar la máquina de QA y su acceso externo (riesgo RT-02).
A25: T-323.1 | B25: Diagrama de infraestructura nuevo: lo necesitan Infraestructura V2 y el despliegue C4.
A26: T-318.1 y T-319.1 | B26: ADR-017 y ADR-018: su aprobación en Mesa desbloquea la terminología de todos los documentos.
A27: T-328.5 | B27: Cargar historias y tareas en GitHub Projects.

Sheet Tareas
A1: ID tarea | B1: Historia | C1: Título de la historia | D1: Frente | E1: Tarea | F1: Responsable | G1: Rol | H1: Tipo | I1: Componente | J1: Entregable S10 | K1: MoSCoW | L1: Ruta crítica | M1: Depende de | N1: Bloquea a | O1: Nivel | P1: Estado | Q1: Fecha inicio | R1: Fecha fin | S1: Nota
A2: T-301.1 | B2: HU-301 | C2: Contratos OpenAPI del incremento publicados antes del código | D2: Contratos y datos de prueba | E2: Extraer del DD V2.0 las operaciones del incremento con sus errores y degradaciones | F2: Sara | G2: Arquitecta | H2: Documento | I2: Identidad, Donación, Campañas | J2: Incremento de valor | K2: Must | L2: Sí | M2: — | N2: T-301.2, T-301.3, T-301.4, T-302.1 | O2: 0 | P2: Pendiente
A3: T-301.2 | B3: HU-301 | C3: Contratos OpenAPI del incremento publicados antes del código | D3: Contratos y datos de prueba | E3: Escribir el OpenAPI de Identidad: sesión, renovación, término y claves públicas | F3: Sara | G3: Arquitecta | H3: Código | I3: Identidad, Donación, Campañas | J3: Incremento de valor | K3: Must | L3: Sí | M3: T-301.1 | N3: T-301.5, T-304.2 | O3: 1 | P3: Pendiente
A4: T-301.3 | B4: HU-301 | C4: Contratos OpenAPI del incremento publicados antes del código | D4: Contratos y datos de prueba | E4: Escribir el OpenAPI de Donación: búsqueda de donante, donación, tamizaje, existencias, despacho, disposición y eventos | F4: Sara | G4: Arquitecta | H4: Código | I4: Identidad, Donación, Campañas | J4: Incremento de valor | K4: Must | L4: Sí | M4: T-301.1 | N4: T-301.5, T-306.2 | O4: 1 | P4: Pendiente
A5: T-301.4 | B5: HU-301 | C5: Contratos OpenAPI del incremento publicados antes del código | D5: Contratos y datos de prueba | E5: Escribir el OpenAPI de Campañas: consulta, detalle, publicación y cierre | F5: Sara | G5: Arquitecta | H5: Código | I5: Identidad, Donación, Campañas | J5: Incremento de valor | K5: Must | L5: Sí | M5: T-301.1 | N5: T-301.5, T-306.4, T-312.2 | O5: 1 | P5: Pendiente
A6: T-301.5 | B6: HU-301 | C6: Contratos OpenAPI del incremento publicados antes del código | D6: Contratos y datos de prueba | E6: Publicar los contratos en redvital-docs, enlazarlos desde cada repositorio y avisar a QA | F6: Sara | G6: Arquitecta | H6: Documento | I6: Identidad, Donación, Campañas | J6: Incremento de valor | K6: Must | L6: Sí | M6: T-301.2, T-301.3, T-301.4 | N6: T-305.1, T-313.3, T-315.3 | O6: 2 | P6: Pendiente | S6: Desde aquí QA puede escribir pruebas contra el contrato
A7: T-302.1 | B7: HU-302 | C7: Datos sintéticos coherentes para las tres bases | D7: Contratos y datos de prueba | E7: Definir el conjunto sintético: bancos, U3 y U4, donantes, campañas por estado y unidades por estado, incluidas vencidas y próximas a vencer | F7: Tomás | G7: QA / Tester | H7: Base de datos | I7: Bases de datos | J7: Incremento de valor | K7: Must | L7: No | M7: T-301.1 | N7: T-302.2, T-325.2 | O7: 1 | P7: Pendiente
A8: T-302.2 | B8: HU-302 | C8: Datos sintéticos coherentes para las tres bases | D8: Contratos y datos de prueba | E8: Construir el generador versionado con una sola semilla para db_identidad, db_donacion y db_campana | F8: Tomás | G8: QA / Tester | H8: Base de datos | I8: Bases de datos | J8: Incremento de valor | K8: Must | L8: No | M8: T-302.1, T-304.1, T-306.1, T-312.1 | N8: T-302.3, T-311.3 | O8: 2 | P8: Pendiente | S8: Necesita los esquemas de las tres bases
A9: T-302.3 | B9: HU-302 | C9: Datos sintéticos coherentes para las tres bases | D9: Contratos y datos de prueba | E9: Integrar la carga de datos en los trabajos de migración de cada base | F9: Tomás | G9: QA / Tester | H9: Base de datos | I9: Bases de datos | J9: Incremento de valor | K9: Must | L9: No | M9: T-302.2 | N9: T-302.4, T-314.3 | O9: 3 | P9: Pendiente
A10: T-302.4 | B10: HU-302 | C10: Datos sintéticos coherentes para las tres bases | D10: Contratos y datos de prueba | E10: Verificar identificadores coherentes entre bases y ausencia de causa clínica | F10: Tomás | G10: QA / Tester | H10: Pruebas | I10: Bases de datos | J10: Incremento de valor | K10: Must | L10: No | M10: T-302.3 | N10: — | O10: 4 | P10: Pendiente
A11: T-303.1 | B11: HU-303 | C11: Llave de prueba para firmar tokens en desarrollo y pruebas | D11: Contratos y datos de prueba | E11: Generar el par de llaves de prueba y la utilidad que emite tokens U3, U4 y de servicio con las reivindicaciones de ADR-008 | F11: Sebastián | G11: Desarrollador (.NET) | H11: Código | I11: Identidad | J11: Incremento de valor | K11: Must | L11: No | M11: — | N11: T-303.2 | O11: 0 | P11: Pendiente | S11: Desbloquea a Damián y a Tomás sin esperar a Identidad
A12: T-303.2 | B12: HU-303 | C12: Llave de prueba para firmar tokens en desarrollo y pruebas | D12: Contratos y datos de prueba | E12: Cargar la llave solo en el perfil de desarrollo y en la suite; documentar su uso | F12: Sebastián | G12: Desarrollador (.NET) | H12: Código | I12: Identidad | J12: Incremento de valor | K12: Must | L12: No | M12: T-303.1 | N12: T-303.3, T-306.7, T-312.6, T-325.2 | O12: 1 | P12: Pendiente
A13: T-303.3 | B13: HU-303 | C13: Llave de prueba para firmar tokens en desarrollo y pruebas | D13: Contratos y datos de prueba | E13: Prueba que confirma que la configuración de QA rechaza tokens de la llave de prueba | F13: Sebastián | G13: Desarrollador (.NET) | H13: Pruebas | I13: Identidad | J13: Incremento de valor | K13: Must | L13: No | M13: T-303.2, T-305.2 | N13: T-315.5 | O13: 6 | P13: Pendiente
A14: T-304.1 | B14: HU-304 | C14: Identidad: inicio de sesión y claves públicas | D14: Identidad | E14: Base db_identidad: esquema del incremento, migraciones EF Core y roles de propietario y de servicio | F14: Sebastián | G14: Desarrollador (.NET) | H14: Base de datos | I14: Servicio de Identidad + db_identidad | J14: Incremento de valor | K14: Must | L14: Sí | M14: — | N14: T-302.2, T-304.2, T-330.4 | O14: 0 | P14: Pendiente
A15: T-304.2 | B15: HU-304 | C15: Identidad: inicio de sesión y claves públicas | D15: Identidad | E15: Inicio de sesión: verificación de credenciales con respuesta que no distingue usuario de contraseña | F15: Sebastián | G15: Desarrollador (.NET) | H15: Código | I15: Servicio de Identidad + db_identidad | J15: Incremento de valor | K15: Must | L15: Sí | M15: T-304.1, T-301.2 | N15: T-304.3 | O15: 2 | P15: Pendiente
A16: T-304.3 | B16: HU-304 | C16: Identidad: inicio de sesión y claves públicas | D16: Identidad | E16: Emisión de token RS256 de 15 minutos con institución y ruta territorial, sin dato personal | F16: Sebastián | G16: Desarrollador (.NET) | H16: Código | I16: Servicio de Identidad + db_identidad | J16: Incremento de valor | K16: Must | L16: Sí | M16: T-304.2 | N16: T-304.4, T-330.1, T-330.3 | O16: 3 | P16: Pendiente
A17: T-304.4 | B17: HU-304 | C17: Identidad: inicio de sesión y claves públicas | D17: Identidad | E17: Endpoint de claves públicas (JWKS) | F17: Sebastián | G17: Desarrollador (.NET) | H17: Código | I17: Servicio de Identidad + db_identidad | J17: Incremento de valor | K17: Must | L17: Sí | M17: T-304.3 | N17: T-304.5, T-305.2 | O17: 4 | P17: Pendiente | S17: Primera entrega de Identidad: con esto el gateway ya valida tokens reales
A18: T-304.5 | B18: HU-304 | C18: Identidad: inicio de sesión y claves públicas | D18: Identidad | E18: Pruebas unitarias y de integración de sesión y claves públicas | F18: Sebastián | G18: Desarrollador (.NET) | H18: Pruebas | I18: Servicio de Identidad + db_identidad | J18: Incremento de valor | K18: Must | L18: Sí | M18: T-304.4 | N18: T-314.6 | O18: 5 | P18: Pendiente
A19: T-330.1 | B19: HU-330 | C19: Identidad: renovación, término, token de servicio y auditoría | D19: Identidad | E19: Renovación con sesión de 8 horas y rotación de la credencial de renovación | F19: Sebastián | G19: Desarrollador (.NET) | H19: Código | I19: Servicio de Identidad + db_identidad | J19: Incremento de valor | K19: Must | L19: No | M19: T-304.3 | N19: T-330.2 | O19: 4 | P19: Pendiente
A20: T-330.2 | B20: HU-330 | C20: Identidad: renovación, término, token de servicio y auditoría | D20: Identidad | E20: Término de sesión que invalida la renovación | F20: Sebastián | G20: Desarrollador (.NET) | H20: Código | I20: Servicio de Identidad + db_identidad | J20: Incremento de valor | K20: Must | L20: No | M20: T-330.1 | N20: T-330.5 | O20: 5 | P20: Pendiente
A21: T-330.3 | B21: HU-330 | C21: Identidad: renovación, término, token de servicio y auditoría | D21: Identidad | E21: Emisión del token de servicio de Donación | F21: Sebastián | G21: Desarrollador (.NET) | H21: Código | I21: Servicio de Identidad + db_identidad | J21: Incremento de valor | K21: Must | L21: No | M21: T-304.3 | N21: T-330.5 | O21: 4 | P21: Pendiente
A22: T-330.4 | B22: HU-330 | C22: Identidad: renovación, término, token de servicio y auditoría | D22: Identidad | E22: Serie de auditoría de Identidad y operación interna para registrar las denegaciones del gateway | F22: Sebastián | G22: Desarrollador (.NET) | H22: Base de datos | I22: Servicio de Identidad + db_identidad | J22: Incremento de valor | K22: Must | L22: No | M22: T-304.1 | N22: T-305.4, T-315.8, T-330.5 | O22: 1 | P22: Pendiente | S22: Solo anexado por permisos del rol
A23: T-330.5 | B23: HU-330 | C23: Identidad: renovación, término, token de servicio y auditoría | D23: Identidad | E23: Pruebas de renovación, término, token de servicio y auditoría | F23: Sebastián | G23: Desarrollador (.NET) | H23: Pruebas | I23: Servicio de Identidad + db_identidad | J23: Incremento de valor | K23: Must | L23: No | M23: T-330.2, T-330.3, T-330.4 | N23: T-314.6, T-315.5 | O23: 6 | P23: Pendiente
A24: T-305.1 | B24: HU-305 | C24: Gateway: enrutamiento, validación del token y compuerta por rol | D24: API Gateway | E24: Rutas YARP /v1/* hacia Identidad, Donación y Campañas; excluir /internal/ y el puerto de gestión | F24: Sebastián | G24: Desarrollador (.NET) | H24: Código | I24: API Gateway (YARP) | J24: Incremento de valor | K24: Must | L24: Sí | M24: T-301.5 | N24: T-305.2, T-305.5 | O24: 3 | P24: Pendiente
A25: T-305.2 | B25: HU-305 | C25: Gateway: enrutamiento, validación del token y compuerta por rol | D25: API Gateway | E25: Validación de firma y vigencia del token contra el JWKS de Identidad | F25: Sebastián | G25: Desarrollador (.NET) | H25: Código | I25: API Gateway (YARP) | J25: Incremento de valor | K25: Must | L25: Sí | M25: T-305.1, T-304.4 | N25: T-303.3, T-305.3, T-317.1 | O25: 5 | P25: Pendiente
A26: T-305.3 | B26: HU-305 | C26: Gateway: enrutamiento, validación del token y compuerta por rol | D26: API Gateway | E26: Compuerta por ruta y rol según la matriz del DD para las rutas del incremento | F26: Sebastián | G26: Desarrollador (.NET) | H26: Código | I26: API Gateway (YARP) | J26: Incremento de valor | K26: Must | L26: Sí | M26: T-305.2 | N26: T-305.4, T-305.6 | O26: 6 | P26: Pendiente
A27: T-305.4 | B27: HU-305 | C27: Gateway: enrutamiento, validación del token y compuerta por rol | D27: API Gateway | E27: Envío de las denegaciones a la serie de auditoría de Identidad | F27: Sebastián | G27: Desarrollador (.NET) | H27: Código | I27: API Gateway (YARP) | J27: Incremento de valor | K27: Must | L27: Sí | M27: T-305.3, T-330.4 | N27: T-305.6 | O27: 7 | P27: Pendiente
A28: T-305.5 | B28: HU-305 | C28: Gateway: enrutamiento, validación del token y compuerta por rol | D28: API Gateway | E28: Generación y propagación del identificador de correlación | F28: Sebastián | G28: Desarrollador (.NET) | H28: Código | I28: API Gateway (YARP) | J28: Incremento de valor | K28: Must | L28: Sí | M28: T-305.1 | N28: T-305.6 | O28: 4 | P28: Pendiente
A29: T-305.6 | B29: HU-305 | C29: Gateway: enrutamiento, validación del token y compuerta por rol | D29: API Gateway | E29: Pruebas del gateway | F29: Sebastián | G29: Desarrollador (.NET) | H29: Pruebas | I29: API Gateway (YARP) | J29: Incremento de valor | K29: Must | L29: Sí | M29: T-305.3, T-305.4, T-305.5 | N29: T-314.6, T-315.4 | O29: 8 | P29: Pendiente
A30: T-306.1 | B30: HU-306 | C30: Donación: registro de donación asociada a campaña, con degradación | D30: Donación | E30: Base db_donacion: esquema del incremento con Flyway, roles y tablas de solo anexado sin UPDATE ni DELETE para el rol de servicio | F30: Damián | G30: Desarrollador (Java) | H30: Base de datos | I30: Servicio de Donación + db_donacion | J30: Incremento de valor | K30: Must | L30: Sí | M30: — | N30: T-302.2, T-306.2, T-307.1 | O30: 0 | P30: Pendiente
A31: T-306.2 | B31: HU-306 | C31: Donación: registro de donación asociada a campaña, con degradación | D31: Donación | E31: Búsqueda de donante sobre el conjunto sintético | F31: Damián | G31: Desarrollador (Java) | H31: Código | I31: Servicio de Donación + db_donacion | J31: Incremento de valor | K31: Must | L31: Sí | M31: T-306.1, T-301.3 | N31: T-306.3 | O31: 2 | P31: Pendiente
A32: T-306.3 | B32: HU-306 | C32: Donación: registro de donación asociada a campaña, con degradación | D32: Donación | E32: Registro de donación que genera la unidad resultante y su evento | F32: Damián | G32: Desarrollador (Java) | H32: Código | I32: Servicio de Donación + db_donacion | J32: Incremento de valor | K32: Must | L32: Sí | M32: T-306.2 | N32: T-306.4, T-306.5, T-306.6, T-307.4 | O32: 3 | P32: Pendiente
A33: T-306.4 | B33: HU-306 | C33: Donación: registro de donación asociada a campaña, con degradación | D33: Donación | E33: Adaptador hacia Campañas con plazo de 3 s y resultado tipado; degradación con campania_id nulo declarada | F33: Damián | G33: Desarrollador (Java) | H33: Código | I33: Servicio de Donación + db_donacion | J33: Incremento de valor | K33: Must | L33: Sí | M33: T-306.3, T-301.4 | N33: T-306.7 | O33: 4 | P33: Pendiente | S33: Se prueba con un Campañas simulado hasta que exista T-312.3
A34: T-306.5 | B34: HU-306 | C34: Donación: registro de donación asociada a campaña, con degradación | D34: Donación | E34: Idempotencia del registro de donación (DS-10) | F34: Damián | G34: Desarrollador (Java) | H34: Código | I34: Servicio de Donación + db_donacion | J34: Incremento de valor | K34: Must | L34: Sí | M34: T-306.3 | N34: T-306.7 | O34: 4 | P34: Pendiente
A35: T-306.6 | B35: HU-306 | C35: Donación: registro de donación asociada a campaña, con degradación | D35: Donación | E35: Identificador de correlación en los registros de aplicación | F35: Damián | G35: Desarrollador (Java) | H35: Código | I35: Servicio de Donación + db_donacion | J35: Incremento de valor | K35: Must | L35: Sí | M35: T-306.3 | N35: T-306.7 | O35: 4 | P35: Pendiente
A36: T-306.7 | B36: HU-306 | C36: Donación: registro de donación asociada a campaña, con degradación | D36: Donación | E36: Pruebas del servicio con tokens de la llave de prueba | F36: Damián | G36: Desarrollador (Java) | H36: Pruebas | I36: Servicio de Donación + db_donacion | J36: Incremento de valor | K36: Must | L36: Sí | M36: T-303.2, T-306.4, T-306.5, T-306.6 | N36: T-314.6, T-315.4 | O36: 5 | P36: Pendiente
A37: T-307.1 | B37: HU-307 | C37: Donación: motor de transiciones con el catálogo completo | D37: Donación | E37: Catálogo transicion_valida con las 13 transiciones del DD, cargado por migración | F37: Damián | G37: Desarrollador (Java) | H37: Base de datos | I37: Servicio de Donación + db_donacion | J37: Incremento de valor | K37: Must | L37: Sí | M37: T-306.1 | N37: T-307.2 | O37: 1 | P37: Pendiente
A38: T-307.2 | B38: HU-307 | C38: Donación: motor de transiciones con el catálogo completo | D38: Donación | E38: Motor único que lee el catálogo, rechaza lo no listado sin cambiar estado y registra el intento | F38: Damián | G38: Desarrollador (Java) | H38: Código | I38: Servicio de Donación + db_donacion | J38: Incremento de valor | K38: Must | L38: Sí | M38: T-307.1 | N38: T-307.3, T-307.4, T-308.1, T-309.1, T-310.2, T-311.1 | O38: 2 | P38: Pendiente
A39: T-307.3 | B39: HU-307 | C39: Donación: motor de transiciones con el catálogo completo | D39: Donación | E39: Invocación aislada del motor, sin base de datos, para recorrer los 82 casos | F39: Damián | G39: Desarrollador (Java) | H39: Código | I39: Servicio de Donación + db_donacion | J39: Incremento de valor | K39: Must | L39: Sí | M39: T-307.2 | N39: T-315.2 | O39: 3 | P39: Pendiente | S39: Habilita EC-36
A40: T-307.4 | B40: HU-307 | C40: Donación: motor de transiciones con el catálogo completo | D40: Donación | E40: Hacer pasar el alta de la unidad de T-306.3 por el motor | F40: Damián | G40: Desarrollador (Java) | H40: Código | I40: Servicio de Donación + db_donacion | J40: Incremento de valor | K40: Must | L40: Sí | M40: T-307.2, T-306.3 | N40: — | O40: 4 | P40: Pendiente
...

Sheet Historias
A1: Historia | B1: Título | C1: Frente | D1: Responsable | E1: MoSCoW | F1: Pts | G1: Componente | H1: Entregable S10 | I1: Origen | J1: Ruta crítica | K1: Tareas | L1: Tareas hechas | M1: Avance
A2: HU-301 | B2: Contratos OpenAPI del incremento publicados antes del código | C2: Contratos y datos de prueba | D2: Sara | E2: Must | F2: 2 | G2: Identidad, Donación, Campañas | H2: Incremento de valor | I2: DD V2.0, EC-22 | J2: Sí | K2: =COUNTIF(Tareas!$B$2:$B$135,A2) -> 5 | L2: =COUNTIFS(Tareas!$B$2:$B$135,A2,Tareas!$P$2:$P$135,"Hecha") -> 0 | M2: =IF(K2=0,0,L2/K2) -> 0
A3: HU-302 | B3: Datos sintéticos coherentes para las tres bases | C3: Contratos y datos de prueba | D3: Tomás | E3: Must | F3: 3 | G3: Bases de datos | H3: Incremento de valor | I3: DD V2.0, EC-23 | J3: No | K3: =COUNTIF(Tareas!$B$2:$B$135,A3) -> 4 | L3: =COUNTIFS(Tareas!$B$2:$B$135,A3,Tareas!$P$2:$P$135,"Hecha") -> 0 | M3: =IF(K3=0,0,L3/K3) -> 0
A4: HU-303 | B4: Llave de prueba para firmar tokens en desarrollo y pruebas | C4: Contratos y datos de prueba | D4: Sebastián | E4: Must | F4: 1 | G4: Identidad | H4: Incremento de valor | I4: ADR-008 | J4: No | K4: =COUNTIF(Tareas!$B$2:$B$135,A4) -> 3 | L4: =COUNTIFS(Tareas!$B$2:$B$135,A4,Tareas!$P$2:$P$135,"Hecha") -> 0 | M4: =IF(K4=0,0,L4/K4) -> 0
A5: HU-304 | B5: Identidad: inicio de sesión y claves públicas | C5: Identidad | D5: Sebastián | E5: Must | F5: 3 | G5: Servicio de Identidad + db_identidad | H5: Incremento de valor | I5: RF-23, ADR-008, EC-03 | J5: Sí | K5: =COUNTIF(Tareas!$B$2:$B$135,A5) -> 5 | L5: =COUNTIFS(Tareas!$B$2:$B$135,A5,Tareas!$P$2:$P$135,"Hecha") -> 0 | M5: =IF(K5=0,0,L5/K5) -> 0
A6: HU-330 | B6: Identidad: renovación, término, token de servicio y auditoría | C6: Identidad | D6: Sebastián | E6: Must | F6: 2 | G6: Servicio de Identidad + db_identidad | H6: Incremento de valor | I6: RF-24, ADR-008, ADR-016, EC-03 | J6: No | K6: =COUNTIF(Tareas!$B$2:$B$135,A6) -> 5 | L6: =COUNTIFS(Tareas!$B$2:$B$135,A6,Tareas!$P$2:$P$135,"Hecha") -> 0 | M6: =IF(K6=0,0,L6/K6) -> 0
A7: HU-305 | B7: Gateway: enrutamiento, validación del token y compuerta por rol | C7: API Gateway | D7: Sebastián | E7: Must | F7: 3 | G7: API Gateway (YARP) | H7: Incremento de valor | I7: ADR-007, ADR-011, RNF-02 | J7: Sí | K7: =COUNTIF(Tareas!$B$2:$B$135,A7) -> 6 | L7: =COUNTIFS(Tareas!$B$2:$B$135,A7,Tareas!$P$2:$P$135,"Hecha") -> 0 | M7: =IF(K7=0,0,L7/K7) -> 0
A8: HU-306 | B8: Donación: registro de donación asociada a campaña, con degradación | C8: Donación | D8: Damián | E8: Must | F8: 5 | G8: Servicio de Donación + db_donacion | H8: Incremento de valor | I8: RF-03, RF-04, EC-08, EC-10 | J8: Sí | K8: =COUNTIF(Tareas!$B$2:$B$135,A8) -> 7 | L8: =COUNTIFS(Tareas!$B$2:$B$135,A8,Tareas!$P$2:$P$135,"Hecha") -> 0 | M8: =IF(K8=0,0,L8/K8) -> 0
A9: HU-307 | B9: Donación: motor de transiciones con el catálogo completo | C9: Donación | D9: Damián | E9: Must | F9: 3 | G9: Servicio de Donación + db_donacion | H9: Incremento de valor | I9: DS-03, EC-04, EC-36 | J9: Sí | K9: =COUNTIF(Tareas!$B$2:$B$135,A9) -> 4 | L9: =COUNTIFS(Tareas!$B$2:$B$135,A9,Tareas!$P$2:$P$135,"Hecha") -> 0 | M9: =IF(K9=0,0,L9/K9) -> 0
A10: HU-308 | B10: Donación: ingreso a tamizaje y veredicto apto / no apto | C10: Donación | D10: Damián | E10: Must | F10: 2 | G10: Servicio de Donación | H10: Incremento de valor | I10: RF-05, RNF-01, EC-02 | J10: Sí | K10: =COUNTIF(Tareas!$B$2:$B$135,A10) -> 3 | L10: =COUNTIFS(Tareas!$B$2:$B$135,A10,Tareas!$P$2:$P$135,"Hecha") -> 0 | M10: =IF(K10=0,0,L10/K10) -> 0
A11: HU-309 | B11: Donación: consulta de existencias filtrada por institución | C11: Donación | D11: Damián | E11: Must | F11: 2 | G11: Servicio de Donación | H11: Incremento de valor | I11: RF-07, RNF-02, EC-01 | J11: Sí | K11: =COUNTIF(Tareas!$B$2:$B$135,A11) -> 4 | L11: =COUNTIFS(Tareas!$B$2:$B$135,A11,Tareas!$P$2:$P$135,"Hecha") -> 0 | M11: =IF(K11=0,0,L11/K11) -> 0
A12: HU-310 | B12: Donación: despacho y disposición final con confirmación | C12: Donación | D12: Damián | E12: Must | F12: 3 | G12: Servicio de Donación | H12: Incremento de valor | I12: RF-06, EC-12, EC-19, EC-39 | J12: No | K12: =COUNTIF(Tareas!$B$2:$B$135,A12) -> 4 | L12: =COUNTIFS(Tareas!$B$2:$B$135,A12,Tareas!$P$2:$P$135,"Hecha") -> 0 | M12: =IF(K12=0,0,L12/K12) -> 0
A13: HU-311 | B13: Donación: exclusión automática de unidades vencidas | C13: Donación | D13: Damián | E13: Must | F13: 3 | G13: Servicio de Donación | H13: Incremento de valor | I13: RF-18, EC-13, EC-33 | J13: No | K13: =COUNTIF(Tareas!$B$2:$B$135,A13) -> 3 | L13: =COUNTIFS(Tareas!$B$2:$B$135,A13,Tareas!$P$2:$P$135,"Hecha") -> 0 | M13: =IF(K13=0,0,L13/K13) -> 0
... A31: HU-329 | B31: Presentación de la Semana 10 y entrega en buzón | C31: Gestión | D31: Carlos | E31: Must | F31: 2 | G31: Documentación | H31: Presentación | I31: Cronograma S10 | J31: Sí | K31: =COUNTIF(Tareas!$B$2:$B$135,A31) -> 4 | L31: =COUNTIFS(Tareas!$B$2:$B$135,A31,Tareas!$P$2:$P$135,"Hecha") -> 0 | M31: =IF(K31=0,0,L31/K31) -> 0
A32: Total | F32: =SUM(F2:F31) -> 86 | K32: =SUM(K2:K31) -> 134 | L32: =SUM(L2:L31) -> 0 | M32: =IF(K32=0,0,L32/K32) -> 0

Sheet Carga por persona
A1: Persona | B1: Rol | C1: Historias | D1: Pts | E1: Horas equivalentes | F1: Tareas | G1: Pendientes | H1: En curso | I1: Bloqueadas | J1: Hechas | K1: Avance
A2: Damián | B2: Desarrollador (Java) | C2: =COUNTIF(Historias!$D$2:$D$31,A2) -> 6 | D2: =SUMIF(Historias!$D$2:$D$31,A2,Historias!$F$2:$F$31) -> 18 | E2: =D2*$B$13 -> 36 | F2: =COUNTIF(Tareas!$F$2:$F$135,A2) -> 25 | G2: =COUNTIFS(Tareas!$F$2:$F$135,A2,Tareas!$P$2:$P$135,"Pendiente") -> 25 | H2: =COUNTIFS(Tareas!$F$2:$F$135,A2,Tareas!$P$2:$P$135,"En curso") -> 0 | I2: =COUNTIFS(Tareas!$F$2:$F$135,A2,Tareas!$P$2:$P$135,"Bloqueada") -> 0 | J2: =COUNTIFS(Tareas!$F$2:$F$135,A2,Tareas!$P$2:$P$135,"Hecha") -> 0 | K2: =IF(F2=0,0,J2/F2) -> 0
A3: Tomás | B3: QA / Tester | C3: =COUNTIF(Historias!$D$2:$D$31,A3) -> 4 | D3: =SUMIF(Historias!$D$2:$D$31,A3,Historias!$F$2:$F$31) -> 18 | E3: =D3*$B$13 -> 36 | F3: =COUNTIF(Tareas!$F$2:$F$135,A3) -> 21 | G3: =COUNTIFS(Tareas!$F$2:$F$135,A3,Tareas!$P$2:$P$135,"Pendiente") -> 21 | H3: =COUNTIFS(Tareas!$F$2:$F$135,A3,Tareas!$P$2:$P$135,"En curso") -> 0 | I3: =COUNTIFS(Tareas!$F$2:$F$135,A3,Tareas!$P$2:$P$135,"Bloqueada") -> 0 | J3: =COUNTIFS(Tareas!$F$2:$F$135,A3,Tareas!$P$2:$P$135,"Hecha") -> 0 | K3: =IF(F3=0,0,J3/F3) -> 0
A4: Sebastián | B4: Desarrollador (.NET) | C4: =COUNTIF(Historias!$D$2:$D$31,A4) -> 5 | D4: =SUMIF(Historias!$D$2:$D$31,A4,Historias!$F$2:$F$31) -> 14 | E4: =D4*$B$13 -> 28 | F4: =COUNTIF(Tareas!$F$2:$F$135,A4) -> 25 | G4: =COUNTIFS(Tareas!$F$2:$F$135,A4,Tareas!$P$2:$P$135,"Pendiente") -> 25 | H4: =COUNTIFS(Tareas!$F$2:$F$135,A4,Tareas!$P$2:$P$135,"En curso") -> 0 | I4: =COUNTIFS(Tareas!$F$2:$F$135,A4,Tareas!$P$2:$P$135,"Bloqueada") -> 0 | J4: =COUNTIFS(Tareas!$F$2:$F$135,A4,Tareas!$P$2:$P$135,"Hecha") -> 0 | K4: =IF(F4=0,0,J4/F4) -> 0
A5: Sara | B5: Arquitecta | C5: =COUNTIF(Historias!$D$2:$D$31,A5) -> 5 | D5: =SUMIF(Historias!$D$2:$D$31,A5,Historias!$F$2:$F$31) -> 12 | E5: =D5*$B$13 -> 24 | F5: =COUNTIF(Tareas!$F$2:$F$135,A5) -> 20 | G5: =COUNTIFS(Tareas!$F$2:$F$135,A5,Tareas!$P$2:$P$135,"Pendiente") -> 20 | H5: =COUNTIFS(Tareas!$F$2:$F$135,A5,Tareas!$P$2:$P$135,"En curso") -> 0 | I5: =COUNTIFS(Tareas!$F$2:$F$135,A5,Tareas!$P$2:$P$135,"Bloqueada") -> 0 | J5: =COUNTIFS(Tareas!$F$2:$F$135,A5,Tareas!$P$2:$P$135,"Hecha") -> 0 | K5: =IF(F5=0,0,J5/F5) -> 0
A6: Veli | B6: DevOps | C6: =COUNTIF(Historias!$D$2:$D$31,A6) -> 3 | D6: =SUMIF(Historias!$D$2:$D$31,A6,Historias!$F$2:$F$31) -> 8 | E6: =D6*$B$13 -> 16 | F6: =COUNTIF(Tareas!$F$2:$F$135,A6) -> 15 | G6: =COUNTIFS(Tareas!$F$2:$F$135,A6,Tareas!$P$2:$P$135,"Pendiente") -> 15 | H6: =COUNTIFS(Tareas!$F$2:$F$135,A6,Tareas!$P$2:$P$135,"En curso") -> 0 | I6: =COUNTIFS(Tareas!$F$2:$F$135,A6,Tareas!$P$2:$P$135,"Bloqueada") -> 0 | J6: =COUNTIFS(Tareas!$F$2:$F$135,A6,Tareas!$P$2:$P$135,"Hecha") -> 0 | K6: =IF(F6=0,0,J6/F6) -> 0
A7: Alex | B7: Product Owner | C7: =COUNTIF(Historias!$D$2:$D$31,A7) -> 3 | D7: =SUMIF(Historias!$D$2:$D$31,A7,Historias!$F$2:$F$31) -> 8 | E7: =D7*$B$13 -> 16 | F7: =COUNTIF(Tareas!$F$2:$F$135,A7) -> 13 | G7: =COUNTIFS(Tareas!$F$2:$F$135,A7,Tareas!$P$2:$P$135,"Pendiente") -> 13 | H7: =COUNTIFS(Tareas!$F$2:$F$135,A7,Tareas!$P$2:$P$135,"En curso") -> 0 | I7: =COUNTIFS(Tareas!$F$2:$F$135,A7,Tareas!$P$2:$P$135,"Bloqueada") -> 0 | J7: =COUNTIFS(Tareas!$F$2:$F$135,A7,Tareas!$P$2:$P$135,"Hecha") -> 0 | K7: =IF(F7=0,0,J7/F7) -> 0
A8: Carlos | B8: Scrum Master / PM | C8: =COUNTIF(Historias!$D$2:$D$31,A8) -> 4 | D8: =SUMIF(Historias!$D$2:$D$31,A8,Historias!$F$2:$F$31) -> 8 | E8: =D8*$B$13 -> 16 | F8: =COUNTIF(Tareas!$F$2:$F$135,A8) -> 15 | G8: =COUNTIFS(Tareas!$F$2:$F$135,A8,Tareas!$P$2:$P$135,"Pendiente") -> 15 | H8: =COUNTIFS(Tareas!$F$2:$F$135,A8,Tareas!$P$2:$P$135,"En curso") -> 0 | I8: =COUNTIFS(Tareas!$F$2:$F$135,A8,Tareas!$P$2:$P$135,"Bloqueada") -> 0 | J8: =COUNTIFS(Tareas!$F$2:$F$135,A8,Tareas!$P$2:$P$135,"Hecha") -> 0 | K8: =IF(F8=0,0,J8/F8) -> 0
A9: Total | C9: =SUM(C2:C8) -> 30 | D9: =SUM(D2:D8) -> 86 | E9: =SUM(E2:E8) -> 172 | F9: =SUM(F2:F8) -> 134 | G9: =SUM(G2:G8) -> 134 | H9: =SUM(H2:H8) -> 0 | I9: =SUM(I2:I8) -> 0 | J9: =SUM(J2:J8) -> 0 | K9: =IF(F9=0,0,J9/F9) -> 0
A12: Supuestos (celdas en azul: editables)
A13: Horas por punto (referencia) | B13: 2 | C13: Referencia de encaje acordada en el backlog; el seguimiento del sprint es en puntos.
A14: Horas disponibles por persona en el sprint | B14: 18 | C14: 9 h/semana × 2 semanas (Documento de Proyecto). El equipo retiró el tope de 16 h de tarea.
A15: Capacidad nominal del equipo (h) | B15: =B14*COUNTA(A2:A8) -> 126
A16: Horas equivalentes comprometidas | B16: =E9 -> 172
A17: Diferencia (capacidad − compromiso) | B17: =B15-B16 -> -46
A18: En rojo, en la columna Horas equivalentes: personas por encima de sus horas disponibles.

Sheet Entregables S10
A1: Entregable de la Semana 10 | B1: Versión | C1: Historias | D1: Responsable principal | E1: Tarea que lo emite
A2: Presentación de la entrega (máx. 40 min) y buzón | B2: — | C2: HU-328, HU-329 | D2: Carlos | E2: T-329.4
A3: Despliegue de componentes en QA | B3: — | C3: HU-313, HU-314 | D3: Veli | E3: T-314.6
A4: Informe de pruebas | B4: — | C4: HU-315, HU-316 | D4: Tomás | E4: T-316.3
A5: Incremento de valor | B5: — | C5: HU-301 a HU-312, HU-330, HU-317 | D5: Sebastián, Damián | E5: T-314.6
A6: Documento de Requerimientos | B6: SRS V4 | C6: HU-324 | D6: Alex | E6: T-324.4
A7: Backlog | B7: Backlog V4 | C7: HU-327 | D7: Alex | E7: T-327.3
A8: Documento de Arquitectura | B8: SAD V3 | C8: HU-318, HU-319, HU-321 | D8: Sara | E8: T-321.2
A9: Documento de Diseño Detallado | B9: DD V3 | C9: HU-322 | D9: Alex | E9: T-322.5
A10: Documento de Infraestructura | B10: Infraestructura V2 | C10: HU-323 | D10: Veli | E10: T-323.4
A11: Documento de Diseño (vistas 4+1 y C4) | B11: SDD V2 | C11: HU-320 | D11: Sara | E11: T-320.6
A12: Documento de Pruebas | B12: TD V1 | C12: HU-325 | D12: Tomás | E12: T-325.6

Sheet Could
A1: ID | B1: Título | C1: Origen | D1: Pts | E1: Escenarios que habilita | F1: Depende de | G1: Nota
A2: C-01 | B2: Web: registro de donación, tamizaje, despacho y diálogo de desecho | C2: RF-03, RF-05, RF-06 | D2: 5 | E2: EC-19 y EC-41 completos, EC-28 | F2: T-317.3, T-306.3, T-308.2, T-310.2
A3: C-02 | B3: Servicio Institucional + db_institucional: jerarquía, instituciones y vista territorial del coordinador | C3: RF-09, RNF-02 | D3: 5 | E3: EC-01 con U5 | F3: T-305.1, T-303.1 | G3: Necesita un responsable .NET
A4: C-03 | B4: Creación y edición de campañas | C4: RF-08 | D4: 2 | E4: — | F4: C-02, T-312.2 | G4: Arista 10: Campañas pide la ruta territorial a Institucional
A5: C-04 | B5: Fraccionamiento de la donación en componentes | C5: RF-03 | D5: 3 | E5: — | F5: T-307.2
A6: C-05 | B6: Prometheus y Grafana en QA (entradas 31 y 32) | C6: Herramientas V3.0 | D6: 3 | E6: — | F6: T-314.2
A7: C-06 | B7: Alertas de escasez y de vencimiento próximo | C7: RF-19, RF-20 | D7: 3 | E7: — | F7: T-309.1, T-311.1
A8: C-07 | B8: Primera campaña de carga con Gatling sobre el inventario | C8: RNF-04 | D8: 5 | E8: — | F8: T-314.6, C-05
A9: C-08 | B9: Registro voluntario de donante (anónimo y con perfil) | C9: RF-01, RNF-03 | D9: 5 | E9: EC-17 | F9: T-306.1, T-330.3
